Workbook

Sheet Concrete
A1: Material Properties — Concrete
A3: Material Name | B3: SI Units (IS 456) | I3: US Customary Units (converted / ACI 318 reference)
B4: Grade fck (MPa) | C4: Modulus of Elasticity Ec (MPa) | D4: Poisson's Ratio | E4: Shear Modulus G (MPa) | F4: Unit Weight (kN/m3) | G4: Mass Density (kg/m3) | H4: Thermal Coeff. (1/C) | I4: f'c (psi) | J4: f'c (ksi) | K4: Ec (converted) (psi) | L4: Ec (converted) (ksi) | M4: ACI 318 Ec = 57000√f'c (psi) | N4: Unit Weight (pcf) | O4: Thermal Coeff. (1/F)
A5: M20 | B5: 20 | C5: =ROUND(5000*SQRT(B5),0) -> 22361 | D5: 0.2 | E5: =ROUND(C5/(2*(1+D5)),0) -> 9317 | F5: 25 | G5: =ROUND(F5*1000/9.81,0) -> 2548 | H5: 9.9e-06 | I5: =ROUND(B5*145.037738,0) -> 2901 | J5: =ROUND(I5/1000,2) -> 2.9 | K5: =ROUND(C5*145.037738,0) -> 3243189 | L5: =ROUND(K5/1000,0) -> 3243 | M5: =ROUND(57000*SQRT(I5),0) -> 3070073 | N5: =ROUND(F5*6.36588,1) -> 159.1 | O5: =ROUND(H5*9/5,8) -> 1.782e-05
A6: M25 | B6: 25 | C6: =ROUND(5000*SQRT(B6),0) -> 25000 | D6: 0.2 | E6: =ROUND(C6/(2*(1+D6)),0) -> 10417 | F6: 25 | G6: =ROUND(F6*1000/9.81,0) -> 2548 | H6: 9.9e-06 | I6: =ROUND(B6*145.037738,0) -> 3626 | J6: =ROUND(I6/1000,2) -> 3.63 | K6: =ROUND(C6*145.037738,0) -> 3625943 | L6: =ROUND(K6/1000,0) -> 3626 | M6: =ROUND(57000*SQRT(I6),0) -> 3432328 | N6: =ROUND(F6*6.36588,1) -> 159.1 | O6: =ROUND(H6*9/5,8) -> 1.782e-05
A7: M30 | B7: 30 | C7: =ROUND(5000*SQRT(B7),0) -> 27386 | D7: 0.2 | E7: =ROUND(C7/(2*(1+D7)),0) -> 11411 | F7: 25 | G7: =ROUND(F7*1000/9.81,0) -> 2548 | H7: 9.9e-06 | I7: =ROUND(B7*145.037738,0) -> 4351 | J7: =ROUND(I7/1000,2) -> 4.35 | K7: =ROUND(C7*145.037738,0) -> 3972003 | L7: =ROUND(K7/1000,0) -> 3972 | M7: =ROUND(57000*SQRT(I7),0) -> 3759840 | N7: =ROUND(F7*6.36588,1) -> 159.1 | O7: =ROUND(H7*9/5,8) -> 1.782e-05
A8: M35 | B8: 35 | C8: =ROUND(5000*SQRT(B8),0) -> 29580 | D8: 0.2 | E8: =ROUND(C8/(2*(1+D8)),0) -> 12325 | F8: 25 | G8: =ROUND(F8*1000/9.81,0) -> 2548 | H8: 9.9e-06 | I8: =ROUND(B8*145.037738,0) -> 5076 | J8: =ROUND(I8/1000,2) -> 5.08 | K8: =ROUND(C8*145.037738,0) -> 4290216 | L8: =ROUND(K8/1000,0) -> 4290 | M8: =ROUND(57000*SQRT(I8),0) -> 4061025 | N8: =ROUND(F8*6.36588,1) -> 159.1 | O8: =ROUND(H8*9/5,8) -> 1.782e-05
A9: M40 | B9: 40 | C9: =ROUND(5000*SQRT(B9),0) -> 31623 | D9: 0.2 | E9: =ROUND(C9/(2*(1+D9)),0) -> 13176 | F9: 25 | G9: =ROUND(F9*1000/9.81,0) -> 2548 | H9: 9.9e-06 | I9: =ROUND(B9*145.037738,0) -> 5802 | J9: =ROUND(I9/1000,2) -> 5.8 | K9: =ROUND(C9*145.037738,0) -> 4586528 | L9: =ROUND(K9/1000,0) -> 4587 | M9: =ROUND(57000*SQRT(I9),0) -> 4341739 | N9: =ROUND(F9*6.36588,1) -> 159.1 | O9: =ROUND(H9*9/5,8) -> 1.782e-05
A10: M45 | B10: 45 | C10: =ROUND(5000*SQRT(B10),0) -> 33541 | D10: 0.2 | E10: =ROUND(C10/(2*(1+D10)),0) -> 13975 | F10: 25 | G10: =ROUND(F10*1000/9.81,0) -> 2548 | H10: 9.9e-06 | I10: =ROUND(B10*145.037738,0) -> 6527 | J10: =ROUND(I10/1000,2) -> 6.53 | K10: =ROUND(C10*145.037738,0) -> 4864711 | L10: =ROUND(K10/1000,0) -> 4865 | M10: =ROUND(57000*SQRT(I10),0) -> 4605021 | N10: =ROUND(F10*6.36588,1) -> 159.1 | O10: =ROUND(H10*9/5,8) -> 1.782e-05
A11: M50 | B11: 50 | C11: =ROUND(5000*SQRT(B11),0) -> 35355 | D11: 0.2 | E11: =ROUND(C11/(2*(1+D11)),0) -> 14731 | F11: 25 | G11: =ROUND(F11*1000/9.81,0) -> 2548 | H11: 9.9e-06 | I11: =ROUND(B11*145.037738,0) -> 7252 | J11: =ROUND(I11/1000,2) -> 7.25 | K11: =ROUND(C11*145.037738,0) -> 5127809 | L11: =ROUND(K11/1000,0) -> 5128 | M11: =ROUND(57000*SQRT(I11),0) -> 4854044 | N11: =ROUND(F11*6.36588,1) -> 159.1 | O11: =ROUND(H11*9/5,8) -> 1.782e-05
A12: M60 | B12: 60 | C12: =ROUND(5000*SQRT(B12),0) -> 38730 | D12: 0.2 | E12: =ROUND(C12/(2*(1+D12)),0) -> 16138 | F12: 25 | G12: =ROUND(F12*1000/9.81,0) -> 2548 | H12: 9.9e-06 | I12: =ROUND(B12*145.037738,0) -> 8702 | J12: =ROUND(I12/1000,2) -> 8.7 | K12: =ROUND(C12*145.037738,0) -> 5617312 | L12: =ROUND(K12/1000,0) -> 5617 | M12: =ROUND(57000*SQRT(I12),0) -> 5317217 | N12: =ROUND(F12*6.36588,1) -> 159.1 | O12: =ROUND(H12*9/5,8) -> 1.782e-05
A13: User Defined | B13: 27.577008 | C13: =ROUND(5000*SQRT(B13),0) -> 26257 | D13: 0.2 | E13: =ROUND(C13/(2*(1+D13)),0) -> 10940 | F13: 25 | G13: =ROUND(F13*1000/9.81,0) -> 2548 | H13: 9.9e-06 | I13: =ROUND(B13*145.037738,0) -> 4000 | J13: =ROUND(I13/1000,2) -> 4 | K13: =ROUND(C13*145.037738,0) -> 3808256 | L13: =ROUND(K13/1000,0) -> 3808 | M13: =ROUND(57000*SQRT(I13),0) -> 3604997 | N13: =ROUND(F13*6.36588,1) -> 159.1 | O13: =ROUND(H13*9/5,8) -> 1.782e-05

Sheet Rebar
A1: Material Properties — Reinforcing Steel (Rebar)
A2: IS 1786 grades and ASTM A615/A706 grades | SI (MPa) and US Customary (ksi)
A4: Material Name | B4: SI Units (MPa) | G4: US Customary Units (ksi)
B5: Yield Fy (MPa) | C5: Ultimate Fu (MPa) | D5: Modulus Es (MPa) | E5: Poisson's Ratio | F5: Unit Weight (kN/m3) | G5: Yield Fy (ksi) | H5: Ultimate Fu (ksi) | I5: Modulus Es (ksi) | J5: Unit Weight (pcf) | K5: Standard / Code Basis
A6: Fe415 | B6: 415 | C6: 485 | D6: 200000 | E6: 0.3 | F6: 78.5 | G6: =ROUND(B6*145.037738/1000,1) -> 60.2 | H6: =ROUND(C6*145.037738/1000,1) -> 70.3 | I6: =ROUND(D6*145.037738/1000,0) -> 29008 | J6: =ROUND(F6*6.36588,1) -> 499.7 | K6: IS 1786
A7: Fe500 | B7: 500 | C7: 545 | D7: 200000 | E7: 0.3 | F7: 78.5 | G7: =ROUND(B7*145.037738/1000,1) -> 72.5 | H7: =ROUND(C7*145.037738/1000,1) -> 79 | I7: =ROUND(D7*145.037738/1000,0) -> 29008 | J7: =ROUND(F7*6.36588,1) -> 499.7 | K7: IS 1786
A8: Fe500D | B8: 500 | C8: 565 | D8: 200000 | E8: 0.3 | F8: 78.5 | G8: =ROUND(B8*145.037738/1000,1) -> 72.5 | H8: =ROUND(C8*145.037738/1000,1) -> 81.9 | I8: =ROUND(D8*145.037738/1000,0) -> 29008 | J8: =ROUND(F8*6.36588,1) -> 499.7 | K8: IS 1786
A9: Fe550 | B9: 550 | C9: 585 | D9: 200000 | E9: 0.3 | F9: 78.5 | G9: =ROUND(B9*145.037738/1000,1) -> 79.8 | H9: =ROUND(C9*145.037738/1000,1) -> 84.8 | I9: =ROUND(D9*145.037738/1000,0) -> 29008 | J9: =ROUND(F9*6.36588,1) -> 499.7 | K9: IS 1786
A10: Grade 40 | B10: 280 | C10: 420 | D10: 200000 | E10: 0.3 | F10: 78.5 | G10: =ROUND(B10*145.037738/1000,1) -> 40.6 | H10: =ROUND(C10*145.037738/1000,1) -> 60.9 | I10: =ROUND(D10*145.037738/1000,0) -> 29008 | J10: =ROUND(F10*6.36588,1) -> 499.7 | K10: ASTM A615
A11: Grade 60 | B11: 420 | C11: 620 | D11: 200000 | E11: 0.3 | F11: 78.5 | G11: =ROUND(B11*145.037738/1000,1) -> 60.9 | H11: =ROUND(C11*145.037738/1000,1) -> 89.9 | I11: =ROUND(D11*145.037738/1000,0) -> 29008 | J11: =ROUND(F11*6.36588,1) -> 499.7 | K11: ASTM A615
A12: Grade 75 | B12: 520 | C12: 690 | D12: 200000 | E12: 0.3 | F12: 78.5 | G12: =ROUND(B12*145.037738/1000,1) -> 75.4 | H12: =ROUND(C12*145.037738/1000,1) -> 100.1 | I12: =ROUND(D12*145.037738/1000,0) -> 29008 | J12: =ROUND(F12*6.36588,1) -> 499.7 | K12: ASTM A615
A13: Grade 80 | B13: 550 | C13: 725 | D13: 200000 | E13: 0.3 | F13: 78.5 | G13: =ROUND(B13*145.037738/1000,1) -> 79.8 | H13: =ROUND(C13*145.037738/1000,1) -> 105.2 | I13: =ROUND(D13*145.037738/1000,0) -> 29008 | J13: =ROUND(F13*6.36588,1) -> 499.7 | K13: ASTM A615/A706

Sheet Frame Sections - Beam
A1: Frame Section Properties — RCC Beams (Rectangular)
A2: Rectangular RCC sections — sizes span low-rise to high-rise buildings | mm & inch
A4: Section Name | B4: Concrete Material | C4: SI Units (mm) | F4: US Customary Units (in) | J4: Building Category | K4: Notes
C5: Depth D (mm) | D5: Width B (mm) | E5: Gross Area (mm2) | F5: Depth D (in) | G5: Width B (in) | H5: Gross Area (in2) | I5: Section Modulus (in3)
A6: B230X380 | B6: M25 | C6: 380 | D6: 230 | E6: =C6*D6 -> 87400 | F6: =ROUND(C6*0.0393700787,2) -> 14.96 | G6: =ROUND(D6*0.0393700787,2) -> 9.06 | H6: =ROUND(E6*0.0393700787*0.0393700787,1) -> 135.5 | I6: =ROUND(G6*F6^2/6,1) -> 337.9 | J6: Low-rise residential | K6: Typical light residential floor beam
A7: B230X450 | B7: M25 | C7: 450 | D7: 230 | E7: =C7*D7 -> 103500 | F7: =ROUND(C7*0.0393700787,2) -> 17.72 | G7: =ROUND(D7*0.0393700787,2) -> 9.06 | H7: =ROUND(E7*0.0393700787*0.0393700787,1) -> 160.4 | I7: =ROUND(G7*F7^2/6,1) -> 474.1 | J7: Low/mid-rise residential | K7: Typical floor beam
A8: B230X600 | B8: M25 | C8: 600 | D8: 230 | E8: =C8*D8 -> 138000 | F8: =ROUND(C8*0.0393700787,2) -> 23.62 | G8: =ROUND(D8*0.0393700787,2) -> 9.06 | H8: =ROUND(E8*0.0393700787*0.0393700787,1) -> 213.9 | I8: =ROUND(G8*F8^2/6,1) -> 842.4 | J8: Mid-rise commercial | K8: Main / transfer-capable beam
A9: B300X600 | B9: M30 | C9: 600 | D9: 300 | E9: =C9*D9 -> 180000 | F9: =ROUND(C9*0.0393700787,2) -> 23.62 | G9: =ROUND(D9*0.0393700787,2) -> 11.81 | H9: =ROUND(E9*0.0393700787*0.0393700787,1) -> 279 | I9: =ROUND(G9*F9^2/6,1) -> 1098.1 | J9: Mid/high-rise commercial | K9: Long span / heavier load beam
A10: B300X750 | B10: M30 | C10: 750 | D10: 300 | E10: =C10*D10 -> 225000 | F10: =ROUND(C10*0.0393700787,2) -> 29.53 | G10: =ROUND(D10*0.0393700787,2) -> 11.81 | H10: =ROUND(E10*0.0393700787*0.0393700787,1) -> 348.8 | I10: =ROUND(G10*F10^2/6,1) -> 1716.4 | J10: High-rise | K10: Transfer beam
A11: B400X900 | B11: M40 | C11: 900 | D11: 400 | E11: =C11*D11 -> 360000 | F11: =ROUND(C11*0.0393700787,2) -> 35.43 | G11: =ROUND(D11*0.0393700787,2) -> 15.75 | H11: =ROUND(E11*0.0393700787*0.0393700787,1) -> 558 | I11: =ROUND(G11*F11^2/6,1) -> 3295.1 | J11: High-rise / industrial | K11: Heavy transfer / podium beam
A12: B300X450-IND | B12: M30 | C12: 450 | D12: 300 | E12: =C12*D12 -> 135000 | F12: =ROUND(C12*0.0393700787,2) -> 17.72 | G12: =ROUND(D12*0.0393700787,2) -> 11.81 | H12: =ROUND(E12*0.0393700787*0.0393700787,1) -> 209.3 | I12: =ROUND(G12*F12^2/6,1) -> 618.1 | J12: Industrial | K12: Gantry-supporting or heavy-duty floor beam

Sheet Frame Sections - Column
A1: Frame Section Properties — RCC Columns (Rectangular / Square)
A2: Rectangular RCC sections — sizes span low-rise to high-rise buildings | mm & inch
A4: Section Name | B4: Concrete Material | C4: SI Units (mm) | F4: US Customary Units (in) | J4: Building Category | K4: Notes
C5: Depth D (mm) | D5: Width B (mm) | E5: Gross Area (mm2) | F5: Depth D (in) | G5: Width B (in) | H5: Gross Area (in2) | I5: Section Modulus (in3)
A6: C230X230 | B6: M25 | C6: 230 | D6: 230 | E6: =C6*D6 -> 52900 | F6: =ROUND(C6*0.0393700787,2) -> 9.06 | G6: =ROUND(D6*0.0393700787,2) -> 9.06 | H6: =ROUND(E6*0.0393700787*0.0393700787,1) -> 82 | I6: =ROUND(G6*F6^2/6,1) -> 123.9 | J6: Low-rise residential | K6: Minimum practical column, up to G+2
A7: C300X300 | B7: M30 | C7: 300 | D7: 300 | E7: =C7*D7 -> 90000 | F7: =ROUND(C7*0.0393700787,2) -> 11.81 | G7: =ROUND(D7*0.0393700787,2) -> 11.81 | H7: =ROUND(E7*0.0393700787*0.0393700787,1) -> 139.5 | I7: =ROUND(G7*F7^2/6,1) -> 274.5 | J7: Low/mid-rise | K7: Typical residential/commercial column
A8: C450X450 | B8: M30 | C8: 450 | D8: 450 | E8: =C8*D8 -> 202500 | F8: =ROUND(C8*0.0393700787,2) -> 17.72 | G8: =ROUND(D8*0.0393700787,2) -> 17.72 | H8: =ROUND(E8*0.0393700787*0.0393700787,1) -> 313.9 | I8: =ROUND(G8*F8^2/6,1) -> 927.3 | J8: Mid-rise | K8: Mid-rise column, G+8 to G+15 range
A9: C600X600 | B9: M35 | C9: 600 | D9: 600 | E9: =C9*D9 -> 360000 | F9: =ROUND(C9*0.0393700787,2) -> 23.62 | G9: =ROUND(D9*0.0393700787,2) -> 23.62 | H9: =ROUND(E9*0.0393700787*0.0393700787,1) -> 558 | I9: =ROUND(G9*F9^2/6,1) -> 2196.3 | J9: High-rise | K9: Lower-storey column, tall building
A10: C750X750 | B10: M40 | C10: 750 | D10: 750 | E10: =C10*D10 -> 562500 | F10: =ROUND(C10*0.0393700787,2) -> 29.53 | G10: =ROUND(D10*0.0393700787,2) -> 29.53 | H10: =ROUND(E10*0.0393700787*0.0393700787,1) -> 871.9 | I10: =ROUND(G10*F10^2/6,1) -> 4291.8 | J10: High-rise | K10: Podium / transfer-level column
A11: C230X600 | B11: M30 | C11: 600 | D11: 230 | E11: =C11*D11 -> 138000 | F11: =ROUND(C11*0.0393700787,2) -> 23.62 | G11: =ROUND(D11*0.0393700787,2) -> 9.06 | H11: =ROUND(E11*0.0393700787*0.0393700787,1) -> 213.9 | I11: =ROUND(G11*F11^2/6,1) -> 842.4 | J11: Any (wall-hidden) | K11: Wall-hidden / lift-core column
A12: C500X500-IND | B12: M35 | C12: 500 | D12: 500 | E12: =C12*D12 -> 250000 | F12: =ROUND(C12*0.0393700787,2) -> 19.69 | G12: =ROUND(D12*0.0393700787,2) -> 19.69 | H12: =ROUND(E12*0.0393700787*0.0393700787,1) -> 387.5 | I12: =ROUND(G12*F12^2/6,1) -> 1272.3 | J12: Industrial | K12: Heavy-duty industrial / crane-column
A13: User Defined | B13: M30 | C13: 457.26102 | D13: 381.05085 | E13: =C13*D13 -> 174239.7 | F13: =ROUND(C13*0.0393700787,2) -> 18 | G13: =ROUND(D13*0.0393700787,2) -> 15 | H13: =ROUND(E13*0.0393700787*0.0393700787,1) -> 270.1 | I13: =ROUND(G13*F13^2/6,1) -> 810 | J13: Low/mid-rise | K13: Typical residential/commercial column

Sheet Slab Sections
A1: Shell Section Properties — RCC Slabs
A2: mm/in thickness, self-weight in kN/m2 & psf
A4: Section Name | B4: Concrete Material | C4: SI Units | E4: US Customary Units | G4: Building Category | H4: Shell Type | I4: Notes
C5: Thickness (mm) | D5: Self Weight (kN/m2) | E5: Thickness (in) | F5: Self Weight (psf)
A6: S100 | B6: M25 | C6: 100 | D6: =(C6/1000)*VLOOKUP(B6,Concrete!$A$5:$F$12,6,FALSE()) -> 2.5 | E6: =ROUND(C6*0.0393700787,2) -> 3.94 | F6: =ROUND(D6*20.8854,1) -> 52.2 | G6: Low-rise residential | H6: Shell-Thin | I6: Light residential floor/roof slab
A7: S125 | B7: M25 | C7: 125 | D7: =(C7/1000)*VLOOKUP(B7,Concrete!$A$5:$F$12,6,FALSE()) -> 3.125 | E7: =ROUND(C7*0.0393700787,2) -> 4.92 | F7: =ROUND(D7*20.8854,1) -> 65.3 | G7: Residential | H7: Shell-Thin | I7: Typical residential floor slab
A8: S152.46 | B8: M25 | C8: 152.46 | D8: =(C8/1000)*VLOOKUP(B8,Concrete!$A$5:$F$12,6,FALSE()) -> 3.8115 | E8: =ROUND(C8*0.0393700787,2) -> 6 | F8: =ROUND(D8*20.8854,1) -> 79.6 | G8: Commercial | H8: Shell-Thin | I8: Typical commercial floor slab
A9: S175 | B9: M30 | C9: 175 | D9: =(C9/1000)*VLOOKUP(B9,Concrete!$A$5:$F$12,6,FALSE()) -> 4.375 | E9: =ROUND(C9*0.0393700787,2) -> 6.89 | F9: =ROUND(D9*20.8854,1) -> 91.4 | G9: Mid-rise | H9: Shell-Thin | I9: Longer-span office floor slab
A10: S200 | B10: M30 | C10: 200 | D10: =(C10/1000)*VLOOKUP(B10,Concrete!$A$5:$F$12,6,FALSE()) -> 5 | E10: =ROUND(C10*0.0393700787,2) -> 7.87 | F10: =ROUND(D10*20.8854,1) -> 104.4 | G10: High-rise / Podium | H10: Shell-Thin | I10: Podium / transfer slab
A11: S250 | B11: M30 | C11: 250 | D11: =(C11/1000)*VLOOKUP(B11,Concrete!$A$5:$F$12,6,FALSE()) -> 6.25 | E11: =ROUND(C11*0.0393700787,2) -> 9.84 | F11: =ROUND(D11*20.8854,1) -> 130.5 | G11: Industrial / Raft | H11: Shell-Thick | I11: Raft / mat foundation slab
A12: S300 | B12: M35 | C12: 300 | D12: =(C12/1000)*VLOOKUP(B12,Concrete!$A$5:$F$12,6,FALSE()) -> 7.5 | E12: =ROUND(C12*0.0393700787,2) -> 11.81 | F12: =ROUND(D12*20.8854,1) -> 156.6 | G12: Industrial / Heavy | H12: Shell-Thick | I12: Heavy-duty industrial floor slab

Sheet Wall Sections
A1: Shell Section Properties — RCC Shear Walls
A2: mm/in thickness, self-weight in kN/m2 & psf
A4: Section Name | B4: Concrete Material | C4: SI Units | E4: US Customary Units | G4: Building Category | H4: Shell Type | I4: Notes
C5: Thickness (mm) | D5: Self Weight (kN/m2) | E5: Thickness (in) | F5: Self Weight (psf)
A6: W150 | B6: M30 | C6: 150 | D6: =(C6/1000)*VLOOKUP(B6,Concrete!$A$5:$F$12,6,FALSE()) -> 3.75 | E6: =ROUND(C6*0.0393700787,2) -> 5.91 | F6: =ROUND(D6*20.8854,1) -> 78.3 | G6: Low-rise | H6: Shell-Thin | I6: Partition / lightly loaded wall
A7: W200 | B7: M30 | C7: 200 | D7: =(C7/1000)*VLOOKUP(B7,Concrete!$A$5:$F$12,6,FALSE()) -> 5 | E7: =ROUND(C7*0.0393700787,2) -> 7.87 | F7: =ROUND(D7*20.8854,1) -> 104.4 | G7: Mid-rise | H7: Shell-Thin | I7: Typical shear wall
A8: W230 | B8: M35 | C8: 230 | D8: =(C8/1000)*VLOOKUP(B8,Concrete!$A$5:$F$12,6,FALSE()) -> 5.75 | E8: =ROUND(C8*0.0393700787,2) -> 9.06 | F8: =ROUND(D8*20.8854,1) -> 120.1 | G8: Mid-rise | H8: Shell-Thin | I8: Core wall, mid-rise
A9: W300 | B9: M35 | C9: 300 | D9: =(C9/1000)*VLOOKUP(B9,Concrete!$A$5:$F$12,6,FALSE()) -> 7.5 | E9: =ROUND(C9*0.0393700787,2) -> 11.81 | F9: =ROUND(D9*20.8854,1) -> 156.6 | G9: High-rise | H9: Shell-Thick | I9: Core wall, high-rise, mid storeys
A10: W400 | B10: M40 | C10: 400 | D10: =(C10/1000)*VLOOKUP(B10,Concrete!$A$5:$F$12,6,FALSE()) -> 10 | E10: =ROUND(C10*0.0393700787,2) -> 15.75 | F10: =ROUND(D10*20.8854,1) -> 208.9 | G10: High-rise | H10: Shell-Thick | I10: Core wall, high-rise, lower storeys
A11: W500 | B11: M40 | C11: 500 | D11: =(C11/1000)*VLOOKUP(B11,Concrete!$A$5:$F$12,6,FALSE()) -> 12.5 | E11: =ROUND(C11*0.0393700787,2) -> 19.69 | F11: =ROUND(D11*20.8854,1) -> 261.1 | G11: Super-tall / Industrial | H11: Shell-Thick | I11: Heavy core wall, tallest towers / silos
D13: Density of Wall | E13: 1880 | F13: kg/m3

Sheet Live-Dead Loads
A1: Design Loads by Building Occupancy / Nature
A2: Basis: ASCE 7-22 Table 4.3-1 (US) ≈ UBC 1997 Table 16-A | psf primary, kPa converted
A3: Table A — Minimum Uniformly Distributed Live Loads by Occupancy
A5: Occupancy / Building Nature | C5: US Customary (ASCE 7-22 / UBC 16-A) | E5: SI (converted) | G5: Live Load Reduction? | H5: Notes
A6: Category | B6: Building Type | C6: Live Load (psf) | D6: Conc. Load (lb) | E6: Live Load (Pa) | F6: Conc. Load (kN)
A7: Residential | B7: One/two-family dwellings — habitable rooms | C7: 40 | D7: 0 | E7: =(C7/20.8854)*1000 -> 1915.2135 | F7: =ROUND(D7*0.0044482,2) -> 0 | G7: Yes | H7: Sleeping rooms same 40 psf (30 psf in some editions)
A8: Residential | B8: Apartments / hotels — private rooms & corridors | C8: 40 | D8: 0 | E8: =(C8/20.8854)*1000 -> 1915.2135 | F8: =ROUND(D8*0.0044482,2) -> 0 | G8: Yes
A9: Residential | B9: Apartments / hotels — public rooms & corridors | C9: 100 | D9: 0 | E9: =(C9/20.8854)*1000 -> 4788.0337 | F9: =ROUND(D9*0.0044482,2) -> 0 | G9: Yes
A10: Office | B10: Offices | C10: 50 | D10: 2000 | E10: =(C10/20.8854)*1000 -> 2394.0169 | F10: =ROUND(D10*0.0044482,2) -> 8.9 | G10: Yes | H10: Partition allowance min 15 psf added as dead/live per code
A11: Office | B11: Lobbies & first-floor corridors | C11: 100 | D11: 2000 | E11: =(C11/20.8854)*1000 -> 4788.0337 | F11: =ROUND(D11*0.0044482,2) -> 8.9 | G11: Yes
A12: Office | B12: Corridors above first floor | C12: 80 | D12: 2000 | E12: =(C12/20.8854)*1000 -> 3830.427 | F12: =ROUND(D12*0.0044482,2) -> 8.9 | G12: Yes
A13: Assembly | B13: Fixed seats (theatres, churches, stadiums) | C13: 60 | D13: 0 | E13: =(C13/20.8854)*1000 -> 2872.8202 | F13: =ROUND(D13*0.0044482,2) -> 0 | G13: No
A14: Assembly | B14: Movable seats / lobbies | C14: 100 | D14: 0 | E14: =(C14/20.8854)*1000 -> 4788.0337 | F14: =ROUND(D14*0.0044482,2) -> 0 | G14: No
A15: Assembly | B15: Dance halls, gymnasiums, dining, restaurants | C15: 100 | D15: 0 | E15: =(C15/20.8854)*1000 -> 4788.0337 | F15: =ROUND(D15*0.0044482,2) -> 0 | G15: No
A16: Institutional | B16: Classrooms (schools) | C16: 40 | D16: 1000 | E16: =(C16/20.8854)*1000 -> 1915.2135 | F16: =ROUND(D16*0.0044482,2) -> 4.45 | G16: Yes
A17: Institutional | B17: School corridors above first floor | C17: 80 | D17: 1000 | E17: =(C17/20.8854)*1000 -> 3830.427 | F17: =ROUND(D17*0.0044482,2) -> 4.45 | G17: Yes
A18: Institutional | B18: Hospital patient rooms | C18: 40 | D18: 1000 | E18: =(C18/20.8854)*1000 -> 1915.2135 | F18: =ROUND(D18*0.0044482,2) -> 4.45 | G18: Yes
A19: Institutional | B19: Hospital operating rooms / laboratories | C19: 60 | D19: 1000 | E19: =(C19/20.8854)*1000 -> 2872.8202 | F19: =ROUND(D19*0.0044482,2) -> 4.45 | G19: Yes
A20: Institutional | B20: Hospital corridors above first floor | C20: 80 | D20: 1000 | E20: =(C20/20.8854)*1000 -> 3830.427 | F20: =ROUND(D20*0.0044482,2) -> 4.45 | G20: Yes
A21: Library | B21: Reading rooms | C21: 60 | D21: 1000 | E21: =(C21/20.8854)*1000 -> 2872.8202 | F21: =ROUND(D21*0.0044482,2) -> 4.45 | G21: Yes
A22: Library | B22: Stack rooms | C22: 150 | D22: 1000 | E22: =(C22/20.8854)*1000 -> 7182.0506 | F22: =ROUND(D22*0.0044482,2) -> 4.45 | G22: No | H22: Sec 4.7.3 — reduction not permitted
A23: Retail / Stores | B23: Retail — first floor | C23: 100 | D23: 1000 | E23: =(C23/20.8854)*1000 -> 4788.0337 | F23: =ROUND(D23*0.0044482,2) -> 4.45 | G23: Yes
A24: Retail / Stores | B24: Retail — upper floors | C24: 75 | D24: 1000 | E24: =(C24/20.8854)*1000 -> 3591.0253 | F24: =ROUND(D24*0.0044482,2) -> 4.45 | G24: Yes
A25: Industrial | B25: Light manufacturing | C25: 125 | D25: 2000 | E25: =(C25/20.8854)*1000 -> 5985.0422 | F25: =ROUND(D25*0.0044482,2) -> 8.9 | G25: Yes
A26: Industrial | B26: Heavy manufacturing | C26: 250 | D26: 3000 | E26: =(C26/20.8854)*1000 -> 11970.084 | F26: =ROUND(D26*0.0044482,2) -> 13.34 | G26: Yes
A27: Storage | B27: Light storage / warehouse | C27: 125 | D27: 0 | E27: =(C27/20.8854)*1000 -> 5985.0422 | F27: =ROUND(D27*0.0044482,2) -> 0 | G27: Yes
A28: Storage | B28: Heavy storage / warehouse | C28: 250 | D28: 0 | E28: =(C28/20.8854)*1000 -> 11970.084 | F28: =ROUND(D28*0.0044482,2) -> 0 | G28: Yes
A29: Parking | B29: Passenger vehicle garages | C29: 40 | D29: 0 | E29: =(C29/20.8854)*1000 -> 1915.2135 | F29: =ROUND(D29*0.0044482,2) -> 0 | G29: Yes* | H29: *Special provisions apply — ASCE 7 Sec 4.3 / 4.7
A30: Parking | B30: Trucks & buses | C30: 0 | D30: 0 | E30: =(C30/20.8854)*1000 -> 0 | F30: =ROUND(D30*0.0044482,2) -> 0 | G30: n/a | H30: Use AASHTO / site-specific vehicle loading
A31: Circulation | B31: Stairs & exit ways | C31: 100 | D31: 300 | E31: =(C31/20.8854)*1000 -> 4788.0337 | F31: =ROUND(D31*0.0044482,2) -> 1.33 | G31: No | H31: 40 psf permitted for one/two-family dwellings
A32: Roof | B32: Ordinary flat / pitched / curved roofs | C32: 20 | D32: 300 | E32: =(C32/20.8854)*1000 -> 957.60675 | F32: =ROUND(D32*0.0044482,2) -> 1.33 | G32: Yes (4.8)
A33: Roof | B33: Roof gardens / occupied roofs / assembly | C33: 100 | D33: 0 | E33: =(C33/20.8854)*1000 -> 4788.0337 | F33: =ROUND(D33*0.0044482,2) -> 0 | G33: No
A34: Roof | B34: Awnings & canopies (non-fabric) | C34: 5 | D34: 0 | E34: =(C34/20.8854)*1000 -> 239.40169 | F34: =ROUND(D34*0.0044482,2) -> 0 | G34: No | H34: Non-reducible
A35: Balcony | B35: Exterior balconies | C35: 60 | D35: 0 | E35: =(C35/20.8854)*1000 -> 2872.8202 | F35: =ROUND(D35*0.0044482,2) -> 0 | G35: No | H35: 1.5x occupancy served, need not exceed 100 psf
A36: Exterior | B36: Sidewalks / driveways / yards subject to trucking | C36: 250 | D36: 8000 | E36: =(C36/20.8854)*1000 -> 11970.084 | F36: =ROUND(D36*0.0044482,2) -> 35.59 | G36: Yes
A38: Values summarize ASCE 7-22 Table 4.3-1 (and its long-standing UBC Table 16-A equivalent) for the most common occupancies. The Engineer of Record must verify the exact occupancy classification, confirm current-edition values, and apply live load reduction (ASCE 7 Sec. 4.7) or roof reduction (Sec. 4.8) only where explicitly permitted.
A41: Table B — Typical Superimposed Dead Load Allowances (engineering practice, not code-mandated)
A42: Component | B42: SI | C42: US Customary
B43: kN/m2 | C43: psf
A44: Floor finish (tile/screed) | B44: 1 | C44: =ROUND(B44*20.8854,1) -> 20.9
...

Sheet Seismic Design Parameters
A1: Seismic Design Parameters — ASCE 7-22 & UBC 1997
A2: Site hazard (Ss, S1, Z) is location-specific — obtain from https://asce7hazardtool.online or local AHJ
A3: PART 1 — ASCE 7-22 (current US practice)
A4: 1A. Site & Design Spectral Parameters
A5: Ss — Mapped MCER short-period spectral accel. (g) | E5: 1.5
A6: S1 — Mapped MCER 1-second spectral accel. (g) | E6: 0.6
A7: Site Class (A-F) | E7: D
A8: Risk Category (I-IV) | E8: II
A10: Reference Table — Site Coefficient Fa (Table 11.4-1)
A11: Site Class | B11: Ss≤0.25 | C11: Ss=0.5 | D11: Ss=0.75 | E11: Ss=1.0 | F11: Ss≥1.25
A12: A | B12: 0.8 | C12: 0.8 | D12: 0.8 | E12: 0.8 | F12: 0.8
A13: B | B13: 0.9 | C13: 0.9 | D13: 0.9 | E13: 0.9 | F13: 0.9
A14: C | B14: 1.3 | C14: 1.3 | D14: 1.2 | E14: 1.2 | F14: 1.2
A15: D | B15: 1.6 | C15: 1.4 | D15: 1.2 | E15: 1.1 | F15: 1
A16: E | B16: 2.4 | C16: 1.7 | D16: 1.3 | E16: 1.1 | F16: 0.9
A17: F | B17: Site-specific ground motion analysis required (ASCE 7 Sec. 11.4.8)
A19: Reference Table — Site Coefficient Fv (Table 11.4-2)
A20: Site Class | B20: S1≤0.1 | C20: S1=0.2 | D20: S1=0.3 | E20: S1=0.4 | F20: S1≥0.5
A21: A | B21: 0.8 | C21: 0.8 | D21: 0.8 | E21: 0.8 | F21: 0.8
A22: B | B22: 0.8 | C22: 0.8 | D22: 0.8 | E22: 0.8 | F22: 0.8
A23: C | B23: 1.5 | C23: 1.5 | D23: 1.5 | E23: 1.5 | F23: 1.4
A24: D | B24: 2.4 | C24: 2.2 | D24: 2 | E24: 1.9 | F24: 1.8
A25: E | B25: 4.2 | C25: 3.3 | D25: 2.8 | E25: 2.4 | F25: 2.2
A26: F | B26: Site-specific ground motion analysis required (ASCE 7 Sec. 11.4.8)
A28: 1B. Computed Design Values
A29: Fa (from table above, nearest Ss column) | E29: =INDEX(B12:F17,MATCH(E7,A12:A17,0),MATCH(E5,{0,0.26,0.51,0.76,1.01},1)) -> 1
A30: Fv (from table above, nearest S1 column) | E30: =INDEX(B21:F26,MATCH(E7,A21:A26,0),MATCH(E6,{0,0.11,0.21,0.31,0.41},1)) -> 1.8
A31: SMS = Fa x Ss | E31: =ROUND(E29*E5,3) -> 1.5
A32: SM1 = Fv x S1 | E32: =ROUND(E30*E6,3) -> 1.08
A33: SDS = 2/3 x SMS (design short-period accel.) | E33: =ROUND(2/3*E31,3) -> 1
A34: SD1 = 2/3 x SM1 (design 1-sec accel.) | E34: =ROUND(2/3*E32,3) -> 0.72
A35: Seismic Design Category (governs = more severe of SDS/SD1 checks; Tables 11.6-1/11.6-2) | E35: =IF(OR(E6>=0.75,AND(E8="IV",E6>=0.75)),IF(E8="IV","F","E"),IF(OR(E33>=0.5,E34>=0.2),"D",IF(OR(E33>=0.33,E34>=0.133),"C",IF(OR(E33>=0.167,E34>=0.067),"B","A")))) -> D
A37: 1C. Design Coefficients — Common RC Seismic Force-Resisting Systems (ASCE 7-22 Table 12.2-1)
A38: Seismic Force-Resisting System | B38: R | C38: Ω0 (Omega) | D38: Cd
A39: Bearing Wall — Special RC shear walls | B39: 5 | C39: 2.5 | D39: 5
A40: Bearing Wall — Ordinary RC shear walls | B40: 4 | C40: 2.5 | D40: 4
A41: Building Frame — Special RC shear walls | B41: 6 | C41: 2.5 | D41: 5
A42: Building Frame — Ordinary RC shear walls | B42: 5 | C42: 2.5 | D42: 4.5
A43: Moment Frame — Special RC moment frame (SMRF) | B43: 8 | C43: 3 | D43: 5.5
A44: Moment Frame — Intermediate RC moment frame (IMRF) | B44: 5 | C44: 3 | D44: 4.5
...

Sheet Wind Design Parameters
A1: Wind Design Parameters — ASCE 7-22 & UBC 1997
A2: Basic wind speed V is location-specific — obtain from ASCE 7-22 Fig. 26.5-1 / local wind map
A3: PART 1 — ASCE 7-22 (current US practice)
A4: 1A. Inputs
A5: Basic Wind Speed, V (mph) — Risk Category II | E5: 115
A6: Exposure Category (B, C, or D) | E6: C
A7: Topographic Factor, Kzt (1.0 = flat terrain) | E7: 1
A8: Wind Directionality Factor, Kd (0.85 typ. buildings) | E8: 0.85
A9: Ground Elevation Factor, Ke (1.0 at sea level) | E9: 1
A10: Gust-Effect Factor, G (0.85 rigid structures) | E10: 0.85
A11: Internal Pressure Coeff., GCpi (enclosed = ±0.18) | E11: 0.18
A13: 1B. Exposure Category Terrain Constants (Table 26.11-1)
A14: Exposure | B14: α (alpha) | C14: zg (ft) | D14: zmin (ft) | E14: Description
A15: B | B15: 7 | C15: 1200 | D15: 30 | E15: Urban/suburban, closely-spaced obstructions
A16: C | B16: 9.5 | C16: 900 | D16: 15 | E16: Open terrain, scattered obstructions <30 ft
A17: D | B17: 11.5 | C17: 700 | D17: 7 | E17: Flat, unobstructed coastal / water surfaces
A19: Selected α | E19: =INDEX(B15:B17,MATCH(E6,A15:A17,0)) -> 9.5
A20: Selected zg (ft) | E20: =INDEX(C15:C17,MATCH(E6,A15:A17,0)) -> 900
A21: Selected zmin (ft) | E21: =INDEX(D15:D17,MATCH(E6,A15:A17,0)) -> 15
A23: 1C. Velocity Pressure qz by Height (Kz = 2.01(z/zg)^(2/α); qz = 0.00256 Kz Kzt Kd Ke V², psf)
A24: Height z (ft) | B24: Height z (m) | C24: Kz (-) | D24: qz (psf) | E24: qz (kPa)
A25: 15 | B25: =ROUND(A25/3.28084,1) -> 4.6 | C25: =ROUND(2.01*(MAX(A25,E21)/E20)^(2/E19),3) -> 0.849 | D25: =ROUND(0.00256*C25*E7*E8*E9*E5^2,1) -> 24.4 | E25: =ROUND(D25*0.04788,2) -> 1.17
A26: 20 | B26: =ROUND(A26/3.28084,1) -> 6.1 | C26: =ROUND(2.01*(MAX(A26,E21)/E20)^(2/E19),3) -> 0.902 | D26: =ROUND(0.00256*C26*E7*E8*E9*E5^2,1) -> 26 | E26: =ROUND(D26*0.04788,2) -> 1.24
A27: 30 | B27: =ROUND(A27/3.28084,1) -> 9.1 | C27: =ROUND(2.01*(MAX(A27,E21)/E20)^(2/E19),3) -> 0.982 | D27: =ROUND(0.00256*C27*E7*E8*E9*E5^2,1) -> 28.3 | E27: =ROUND(D27*0.04788,2) -> 1.36
A28: 40 | B28: =ROUND(A28/3.28084,1) -> 12.2 | C28: =ROUND(2.01*(MAX(A28,E21)/E20)^(2/E19),3) -> 1.044 | D28: =ROUND(0.00256*C28*E7*E8*E9*E5^2,1) -> 30 | E28: =ROUND(D28*0.04788,2) -> 1.44
A29: 50 | B29: =ROUND(A29/3.28084,1) -> 15.2 | C29: =ROUND(2.01*(MAX(A29,E21)/E20)^(2/E19),3) -> 1.094 | D29: =ROUND(0.00256*C29*E7*E8*E9*E5^2,1) -> 31.5 | E29: =ROUND(D29*0.04788,2) -> 1.51
A30: 60 | B30: =ROUND(A30/3.28084,1) -> 18.3 | C30: =ROUND(2.01*(MAX(A30,E21)/E20)^(2/E19),3) -> 1.137 | D30: =ROUND(0.00256*C30*E7*E8*E9*E5^2,1) -> 32.7 | E30: =ROUND(D30*0.04788,2) -> 1.57
A31: 80 | B31: =ROUND(A31/3.28084,1) -> 24.4 | C31: =ROUND(2.01*(MAX(A31,E21)/E20)^(2/E19),3) -> 1.208 | D31: =ROUND(0.00256*C31*E7*E8*E9*E5^2,1) -> 34.8 | E31: =ROUND(D31*0.04788,2) -> 1.67
A32: 100 | B32: =ROUND(A32/3.28084,1) -> 30.5 | C32: =ROUND(2.01*(MAX(A32,E21)/E20)^(2/E19),3) -> 1.266 | D32: =ROUND(0.00256*C32*E7*E8*E9*E5^2,1) -> 36.4 | E32: =ROUND(D32*0.04788,2) -> 1.74
A33: 150 | B33: =ROUND(A33/3.28084,1) -> 45.7 | C33: =ROUND(2.01*(MAX(A33,E21)/E20)^(2/E19),3) -> 1.378 | D33: =ROUND(0.00256*C33*E7*E8*E9*E5^2,1) -> 39.7 | E33: =ROUND(D33*0.04788,2) -> 1.9
A34: 200 | B34: =ROUND(A34/3.28084,1) -> 61 | C34: =ROUND(2.01*(MAX(A34,E21)/E20)^(2/E19),3) -> 1.464 | D34: =ROUND(0.00256*C34*E7*E8*E9*E5^2,1) -> 42.1 | E34: =ROUND(D34*0.04788,2) -> 2.02
A35: 300 | B35: =ROUND(A35/3.28084,1) -> 91.4 | C35: =ROUND(2.01*(MAX(A35,E21)/E20)^(2/E19),3) -> 1.595 | D35: =ROUND(0.00256*C35*E7*E8*E9*E5^2,1) -> 45.9 | E35: =ROUND(D35*0.04788,2) -> 2.2
A37: qz is velocity pressure (not final design pressure). Final MWFRS/C&C design pressure p = q·G·Cp − qi·(GCpi), per ASCE 7-22 Ch. 27/28/30 external pressure coefficients (Cp), which depend on building geometry and are not tabulated here. Wind speeds in ASCE 7-22 are ULTIMATE (strength-level, LRFD) — multiply by 0.6 to get ASD-level pressures.
A40: PART 2 — UBC 1997 Wind (legacy code)
A41: 2A. Basic Wind Stagnation Pressure qs (Table 16-F)
A42: Basic Wind Speed (mph) | B42: qs (psf) | C42: Basic Wind Speed (km/h) | D42: qs (kPa)
A43: 70 | B43: 12.6 | C43: =ROUND(A43*1.60934,0) -> 113 | D43: =ROUND(B43*0.04788,2) -> 0.6
A44: 80 | B44: 16.4 | C44: =ROUND(A44*1.60934,0) -> 129 | D44: =ROUND(B44*0.04788,2) -> 0.79
A45: 90 | B45: 20.8 | C45: =ROUND(A45*1.60934,0) -> 145 | D45: =ROUND(B45*0.04788,2) -> 1
A46: 100 | B46: 25.6 | C46: =ROUND(A46*1.60934,0) -> 161 | D46: =ROUND(B46*0.04788,2) -> 1.23
...
