Workbook

Sheet Read Me
A1: Pakistan Seismic Design Data — UBC-97 / BCP-2007 (with ASCE 7 reference)
A2: For use in ETABS seismic load-pattern definition
A4: 1. WHAT THIS WORKBOOK IS
A5: Pakistan does not use ASCE 7 as its legal seismic code. The governing code is the Building Code of Pakistan – Seismic Provisions 2007 (BCP-SP 2007), which adopted the UBC-97 seismic design framework (zone factor Z, soil profile types, Ca/Cv coefficients, base-shear formula). There is no official Ss/S1 (MCE spectral acceleration) map published for Pakistan by a body equivalent to the USGS, so ASCE 7 parameters for Pakistani sites are not a code-defined quantity — any Ss/S1 you use is an engineering approximation, not a code value. This workbook gives you (a) the real, code-based UBC-97/BCP-2007 data you can use directly, and (b) a clearly-labelled APPROXIMATE conversion to ASCE-7-style parameters, for offices that must model in ETABS using the ASCE 7 load pattern.
A7: 2. HOW TO USE THE SHEETS
A8: District Seismic Zones' — find your project district, read its UBC-97 seismic zone and Z factor, sourced from BCP-SP 2007 Table 2.2 (Seismic Zones of Tehsils of Pakistan).
A9: 'UBC-97 Parameters' — the full set of code tables you need in ETABS' UBC 97 seismic definition: Z (16-I), soil profile types (16-J), Ca (16-Q), Cv (16-R), importance factor (16-K), R & Omega0 by system (16-N, abridged), near-source factors (16-S/16-T, Zone 4 only), seismic source types (16-U).
A10: ASCE 7 Approx. Parameters' — site class table (A–F), Fa/Fv tables, and the approximate Ss/S1/SDS/SD1 conversion. Clearly marked NOT AN OFFICIAL CODE VALUE.
A11: ETABS Input Guide' — step-by-step: which numbers to type into which ETABS dialog boxes, for both the UBC 97 and ASCE 7-xx seismic load pattern options.
A13: 3. IMPORTANT LIMITATIONS — PLEASE READ
A14: One zone per district is a SIMPLIFICATION. BCP-2007 actually assigns zones per TEHSIL, and several large districts straddle two zones (e.g. Dera Ghazi Khan district: main city is Zone 2A but its western hill tehsils are Zone 2B; Khyber district ranges 2B–3). The value shown is the zone of the district's main city/headquarters tehsil. For a site outside the main city, verify the specific tehsil in the source table before finalizing a design.
A15: Newly created districts (post-2022 splits, e.g. some KP merged-tribal-district and Balochistan sub-districts) are shown with the zone of their parent tehsil/district; a small number of very recent splits may not be individually reflected.
... A18: ASCE 7 Ss/S1/SDS/SD1 values here are back-calculated from the UBC-97 Z factor using a commonly used engineering approximation (Ss ≈ 2.5·Z, S1 ≈ 1.0·Z), which several Pakistani consultants use for ETABS ASCE-7-mode models in the absence of an official hazard map. This is NOT an ASCE-published or code-mandated value. If the client, regulator, or peer reviewer requires true ASCE 7 hazard values, request a project-specific probabilistic seismic hazard analysis (PSHA) instead of using this approximation.

Sheet District Seismic Zones
A1: District-Wise Seismic Zone (BCP-SP 2007 / UBC-97) — for ETABS Seismic Load Definition
A3: Province / Region | B3: District | C3: UBC-97 / BCP-2007 Seismic Zone | D3: Zone Factor Z (g) | E3: PGA Range (g) | F3: Approx. ASCE-7-style Ss (g) [≈2.5·Z, NOT official] | G3: Approx. ASCE-7-style S1 (g) [≈1.0·Z, NOT official]
A4: Punjab | B4: Attock | C4: 2B | D4: =INDEX('UBC-97 Parameters'!$C$5:$C$9,MATCH(C4,'UBC-97 Parameters'!$B$5:$B$9,0)) -> 0.2 | E4: =INDEX('UBC-97 Parameters'!$D$5:$D$9,MATCH(C4,'UBC-97 Parameters'!$B$5:$B$9,0)) -> 0.16 – 0.24 | F4: =ROUND(D4*2.5,3) -> 0.5 | G4: =ROUND(D4*1,3) -> 0.2
A5: Punjab | B5: Rawalpindi | C5: 2B | D5: =INDEX('UBC-97 Parameters'!$C$5:$C$9,MATCH(C5,'UBC-97 Parameters'!$B$5:$B$9,0)) -> 0.2 | E5: =INDEX('UBC-97 Parameters'!$D$5:$D$9,MATCH(C5,'UBC-97 Parameters'!$B$5:$B$9,0)) -> 0.16 – 0.24 | F5: =ROUND(D5*2.5,3) -> 0.5 | G5: =ROUND(D5*1,3) -> 0.2
A6: Punjab | B6: Jhelum | C6: 2B | D6: =INDEX('UBC-97 Parameters'!$C$5:$C$9,MATCH(C6,'UBC-97 Parameters'!$B$5:$B$9,0)) -> 0.2 | E6: =INDEX('UBC-97 Parameters'!$D$5:$D$9,MATCH(C6,'UBC-97 Parameters'!$B$5:$B$9,0)) -> 0.16 – 0.24 | F6: =ROUND(D6*2.5,3) -> 0.5 | G6: =ROUND(D6*1,3) -> 0.2
A7: Punjab | B7: Chakwal | C7: 2B | D7: =INDEX('UBC-97 Parameters'!$C$5:$C$9,MATCH(C7,'UBC-97 Parameters'!$B$5:$B$9,0)) -> 0.2 | E7: =INDEX('UBC-97 Parameters'!$D$5:$D$9,MATCH(C7,'UBC-97 Parameters'!$B$5:$B$9,0)) -> 0.16 – 0.24 | F7: =ROUND(D7*2.5,3) -> 0.5 | G7: =ROUND(D7*1,3) -> 0.2
A8: Punjab | B8: Gujrat | C8: 2B | D8: =INDEX('UBC-97 Parameters'!$C$5:$C$9,MATCH(C8,'UBC-97 Parameters'!$B$5:$B$9,0)) -> 0.2 | E8: =INDEX('UBC-97 Parameters'!$D$5:$D$9,MATCH(C8,'UBC-97 Parameters'!$B$5:$B$9,0)) -> 0.16 – 0.24 | F8: =ROUND(D8*2.5,3) -> 0.5 | G8: =ROUND(D8*1,3) -> 0.2
A9: Punjab | B9: Sialkot | C9: 2B | D9: =INDEX('UBC-97 Parameters'!$C$5:$C$9,MATCH(C9,'UBC-97 Parameters'!$B$5:$B$9,0)) -> 0.2 | E9: =INDEX('UBC-97 Parameters'!$D$5:$D$9,MATCH(C9,'UBC-97 Parameters'!$B$5:$B$9,0)) -> 0.16 – 0.24 | F9: =ROUND(D9*2.5,3) -> 0.5 | G9: =ROUND(D9*1,3) -> 0.2
A10: Punjab | B10: Narowal | C10: 2B | D10: =INDEX('UBC-97 Parameters'!$C$5:$C$9,MATCH(C10,'UBC-97 Parameters'!$B$5:$B$9,0)) -> 0.2 | E10: =INDEX('UBC-97 Parameters'!$D$5:$D$9,MATCH(C10,'UBC-97 Parameters'!$B$5:$B$9,0)) -> 0.16 – 0.24 | F10: =ROUND(D10*2.5,3) -> 0.5 | G10: =ROUND(D10*1,3) -> 0.2
A11: Punjab | B11: Gujranwala | C11: 2A | D11: =INDEX('UBC-97 Parameters'!$C$5:$C$9,MATCH(C11,'UBC-97 Parameters'!$B$5:$B$9,0)) -> 0.15 | E11: =INDEX('UBC-97 Parameters'!$D$5:$D$9,MATCH(C11,'UBC-97 Parameters'!$B$5:$B$9,0)) -> 0.08 – 0.16 | F11: =ROUND(D11*2.5,3) -> 0.375 | G11: =ROUND(D11*1,3) -> 0.15
A12: Punjab | B12: Hafizabad | C12: 2A | D12: =INDEX('UBC-97 Parameters'!$C$5:$C$9,MATCH(C12,'UBC-97 Parameters'!$B$5:$B$9,0)) -> 0.15 | E12: =INDEX('UBC-97 Parameters'!$D$5:$D$9,MATCH(C12,'UBC-97 Parameters'!$B$5:$B$9,0)) -> 0.08 – 0.16 | F12: =ROUND(D12*2.5,3) -> 0.375 | G12: =ROUND(D12*1,3) -> 0.15
A13: Punjab | B13: Mandi Bahauddin | C13: 2B | D13: =INDEX('UBC-97 Parameters'!$C$5:$C$9,MATCH(C13,'UBC-97 Parameters'!$B$5:$B$9,0)) -> 0.2 | E13: =INDEX('UBC-97 Parameters'!$D$5:$D$9,MATCH(C13,'UBC-97 Parameters'!$B$5:$B$9,0)) -> 0.16 – 0.24 | F13: =ROUND(D13*2.5,3) -> 0.5 | G13: =ROUND(D13*1,3) -> 0.2
A14: Punjab | B14: Sheikhupura | C14: 2A | D14: =INDEX('UBC-97 Parameters'!$C$5:$C$9,MATCH(C14,'UBC-97 Parameters'!$B$5:$B$9,0)) -> 0.15 | E14: =INDEX('UBC-97 Parameters'!$D$5:$D$9,MATCH(C14,'UBC-97 Parameters'!$B$5:$B$9,0)) -> 0.08 – 0.16 | F14: =ROUND(D14*2.5,3) -> 0.375 | G14: =ROUND(D14*1,3) -> 0.15
A15: Punjab | B15: Nankana Sahib | C15: 2A | D15: =INDEX('UBC-97 Parameters'!$C$5:$C$9,MATCH(C15,'UBC-97 Parameters'!$B$5:$B$9,0)) -> 0.15 | E15: =INDEX('UBC-97 Parameters'!$D$5:$D$9,MATCH(C15,'UBC-97 Parameters'!$B$5:$B$9,0)) -> 0.08 – 0.16 | F15: =ROUND(D15*2.5,3) -> 0.375 | G15: =ROUND(D15*1,3) -> 0.15
... A159: Federal | B159: Islamabad Capital Territory | C159: 2B | D159: =INDEX('UBC-97 Parameters'!$C$5:$C$9,MATCH(C159,'UBC-97 Parameters'!$B$5:$B$9,0)) -> 0.2 | E159: =INDEX('UBC-97 Parameters'!$D$5:$D$9,MATCH(C159,'UBC-97 Parameters'!$B$5:$B$9,0)) -> 0.16 – 0.24 | F159: =ROUND(D159*2.5,3) -> 0.5 | G159: =ROUND(D159*1,3) -> 0.2
A162: Legend:
A163: Zone 1 (lowest hazard)
A164: Zone 2A
A165: Zone 2B
A166: Zone 3
A167: Zone 4 (highest hazard)

Sheet UBC-97 Parameters
A1: UBC-97 Seismic Design Tables (as adopted by BCP-SP 2007)
A3: Table 16-I — Seismic Zone Factor Z
B4: Seismic Zone | C4: Z | D4: PGA range (g) used to define zone boundary
B5: 1 | C5: 0.075 | D5: 0.05 – 0.08
B6: 2A | C6: 0.15 | D6: 0.08 – 0.16
B7: 2B | C7: 0.2 | D7: 0.16 – 0.24
B8: 3 | C8: 0.3 | D8: 0.24 – 0.32
B9: 4 | C9: 0.4 | D9: > 0.32
A12: Table 16-J — Soil Profile Types (site-specific geotechnical determination required)
B13: Type | C13: Description | D13: Shear-wave velocity vs (m/s)
B14: SA | C14: Hard rock | D14: > 1500
B15: SB | C15: Rock | D15: 750 – 1500
B16: SC | C16: Very dense soil / soft rock | D16: 350 – 750
B17: SD | C17: Stiff soil | D17: 175 – 350
B18: SE | C18: Soft soil | D18: < 175
B19: SF | C19: Soil requiring site-specific evaluation (e.g. liquefiable, sensitive, organic clays, peat, high-plasticity clay > 25 ft, soft clay > 120 ft) | D19: —
A22: Table 16-Q — Seismic Coefficient Ca
B23: Zone | C23: SA | D23: SB | E23: SC | F23: SD | G23: SE
B24: 1 | C24: 0.06 | D24: 0.08 | E24: 0.09 | F24: 0.12 | G24: 0.19
B25: 2A | C25: 0.15 | D25: 0.15 | E25: 0.18 | F25: 0.22 | G25: 0.3
B26: 2B | C26: 0.2 | D26: 0.2 | E26: 0.24 | F26: 0.28 | G26: 0.34
B27: 3 | C27: 0.3 | D27: 0.3 | E27: 0.33 | F27: 0.36 | G27: 0.36
B28: 4 | C28: 0.4 | D28: 0.4 | E28: 0.44 | F28: 0.44 | G28: 0.36
A29: Note: Zone 4 values require Na (near-source factor); table shows Na=1.0 baseline — multiply by actual Na for Zone-4 sites near a mapped fault.
A31: Table 16-R — Seismic Coefficient Cv
B32: Zone | C32: SA | D32: SB | E32: SC | F32: SD | G32: SE
B33: 1 | C33: 0.06 | D33: 0.08 | E33: 0.13 | F33: 0.18 | G33: 0.26
B34: 2A | C34: 0.15 | D34: 0.15 | E34: 0.25 | F34: 0.32 | G34: 0.5
B35: 2B | C35: 0.2 | D35: 0.2 | E35: 0.32 | F35: 0.4 | G35: 0.64
B36: 3 | C36: 0.3 | D36: 0.3 | E36: 0.45 | F36: 0.54 | G36: 0.84
B37: 4 | C37: 0.4 | D37: 0.4 | E37: 0.6 | F37: 0.72 | G37: 0.96
A38: Note: Zone 4 values require Nv (near-source factor); table shows Nv=1.0 baseline — multiply by actual Nv for Zone-4 sites near a mapped fault.
A40: Table 16-K — Importance Factor I
B41: Occupancy Category | C41: I (Seismic) | D41: Ip (Component)
B42: Essential facilities (hospitals, fire/police stations, emergency response) | C42: 1.5 | D42: 1.5
B43: Hazardous facilities (toxic/explosive substance storage) | C43: 1.25 | D43: 1.5
B44: Special occupancy structures (schools, assembly > 300 people, jails) | C44: 1 | D44: 1
B45: Standard occupancy structures (all others) | C45: 1 | D45: 1
A48: Table 16-N (abridged) — R and Omega0 by Structural System (most common ETABS building types)
B49: Structural System | C49: R | D49: Omega0 | E49: Height limit Zone 3&4 (ft)
...

Sheet ASCE 7 Approx. Parameters
A1: ASCE 7 Reference Data — APPROXIMATE, NOT an official code value for Pakistan
A3: Pakistan has no officially published Ss/S1 (MCE spectral acceleration) hazard map, unlike the USGS map that ASCE 7 relies on in the US. The values below are back-calculated from the UBC-97 zone factor Z using an approximation commonly used in Pakistani practice (Ss ≈ 2.5·Z, S1 ≈ 1.0·Z). Use only where the client/regulator has no objection to this approximation, or better, commission a project-specific PSHA.
A5: Site Class Definitions (ASCE 7, Table 20.3-1) — site-specific geotechnical determination required
B6: Site Class | C6: Description | D6: Vs30 (m/s)
B7: A | C7: Hard rock | D7: > 1500
B8: B | C8: Rock | D8: 760 – 1500
B9: C | C9: Very dense soil/soft rock | D9: 360 – 760
B10: D | C10: Stiff soil (default if unknown, per ASCE 7 §11.4.3) | D10: 180 – 360
B11: E | C11: Soft clay soil | D11: < 180
B12: F | C12: Soils requiring site-specific evaluation | D12: —
A15: Site Coefficient Fa (ASCE 7-16, Table 11.4-1)
B16: Site Class | C16: Ss=0.25 | D16: Ss=0.5 | E16: Ss=0.75 | F16: Ss=1.0 | G16: Ss=1.25 | H16: Ss=1.5
B17: A | C17: 0.8 | D17: 0.8 | E17: 0.8 | F17: 0.8 | G17: 0.8 | H17: 0.8
B18: B | C18: 0.9 | D18: 0.9 | E18: 0.9 | F18: 0.9 | G18: 0.9 | H18: 0.9
B19: C | C19: 1.3 | D19: 1.3 | E19: 1.2 | F19: 1.2 | G19: 1.2 | H19: 1.2
B20: D | C20: 1.6 | D20: 1.4 | E20: 1.2 | F20: 1.1 | G20: 1 | H20: 1
B21: E | C21: 2.4 | D21: 1.7 | E21: 1.3 | F21: See Note | G21: See Note | H21: See Note
A24: Site Coefficient Fv (ASCE 7-16, Table 11.4-2)
B25: Site Class | C25: S1=0.1 | D25: S1=0.2 | E25: S1=0.3 | F25: S1=0.4 | G25: S1=0.5 | H25: S1=0.6
B26: A | C26: 0.8 | D26: 0.8 | E26: 0.8 | F26: 0.8 | G26: 0.8 | H26: 0.8
B27: B | C27: 0.8 | D27: 0.8 | E27: 0.8 | F27: 0.8 | G27: 0.8 | H27: 0.8
B28: C | C28: 1.5 | D28: 1.5 | E28: 1.5 | F28: 1.5 | G28: 1.5 | H28: 1.4
B29: D | C29: 2.4 | D29: 2.2 | E29: 2 | F29: 1.9 | G29: 1.8 | H29: 1.7
B30: E | C30: 4.2 | D30: 3.3 | E30: 2.8 | F30: See Note | G30: See Note | H30: See Note
A33: Design Spectral Acceleration Formulas (ASCE 7 §11.4.4–11.4.5)
B34: SMS = Fa × Ss
B35: SM1 = Fv × S1
B36: SDS = (2/3) × SMS
B37: SD1 = (2/3) × SM1
